<?xml version="1.0"?>

<!-- Sherpa Wheels-->

<robot name ="sherpa_wheel" xmlns:xacro="http://www.ros.org/wiki/xacro">

<!--xacro:arg name="prefix" default="rbsherpa_hl_"/-->
<!--  <xacro:property name="steer_joint_damping" value="0.01" />-->
<!--  <xacro:property name="steer_joint_friction" value="0.01" />-->
  <!--OLD-->
  <!--  <xacro:property name="steer_joint_position_limit" value="2.9" />-->
  <!--NEW-->
  <xacro:property name="steer_joint_position_limit_lower" value="-${PI-0.01}" />
  <xacro:property name="steer_joint_position_limit_upper" value="${PI}" />
<!--  <xacro:property name="wheel_joint_damping" value="10.0" />-->
<!--  <xacro:property name="wheel_joint_friction" value="15.0" />-->


  <!-- Left Steering Wheel -->
  
  <!--   Steering Mechanism -->
  <joint name="$(arg prefix)front_left_wheel_steer_joint" type="revolute">
    <parent link="$(arg prefix)base_link"/>
    <child link="$(arg prefix)front_left_wheel_steer_link"/>
    <origin xyz="${wheel_steer_offset_x} ${wheel_steer_offset_y} ${chassis_field_height+0.010}"/>
    <axis xyz="0 0 1" rpy="0 0 0" />
    <!--<limit effort="30.0" velocity="50.0" lower="-${steer_joint_position_limit}" upper="${steer_joint_position_limit}"/>-->
    <limit effort="30.0" velocity="50.0" lower="${steer_joint_position_limit_lower}" upper="${steer_joint_position_limit_upper}"/>
<!--    <joint_properties damping="${steer_joint_damping}" friction="${steer_joint_friction}"/>-->
  </joint>











<!--  <joint name="$(arg prefix)front_left_wheel_steer_joint" type="fixed">-->
<!--    <parent link="$(arg prefix)base_link"/>-->
<!--    <child link="$(arg prefix)front_left_wheel_steer_link"/>-->
<!--    <origin xyz="${wheel_steer_offset_x} ${wheel_steer_offset_y} ${chassis_field_height+0.010}"/>-->
<!--  </joint>-->

  
  <link name="$(arg prefix)front_left_wheel_steer_link">
    <visual>   
      <origin rpy="0.0 0.0 0.0" xyz="0.0 0.0 -${steer_z/2-0.0120}"/>
      <geometry>
        <mesh filename="package://rbsherpa_hl_description/meshes/wheels/rbsherpa_hl_steer_wheel.dae" />
      </geometry>
    </visual>
	     
    <inertial> 
      <origin rpy="0.0 0.0 0.0" xyz="0.0 0.0 -${steer_z/2+0.2}"/>
	    <mass value="0.1" />
        <!--OLD-->
        <!--<cylinder_inertia m="1.0" r="0.01" h="0.3"/>-->
        <!--NEW-->
        <cylinder_inertia m="0.1" r="0.16" h="0.02"/>
	  </inertial>
	  

  </link>
  <gazebo reference="$(arg prefix)front_left_wheel_steer_link"><material>Gazebo/Grey</material></gazebo>

 






   <!-- wheel -->
   
  <joint name="$(arg prefix)front_left_wheel_traction_joint" type="continuous">
    <parent link="$(arg prefix)front_left_wheel_steer_link"/>
      <child link="$(arg prefix)front_left_wheel_traction_link"/>
      <origin xyz="0.0 -${wheel_traction_offset_y} -${steer_z+0.0210+suspension_z}"/>
      <axis xyz="0.0 1.0 0.0"/>
<!--    <joint_properties damping="${wheel_joint_damping}" friction="${wheel_joint_friction}"/>-->
  </joint>

<!--  <joint name="$(arg prefix)front_left_wheel_traction_joint" type="fixed">-->
<!--    <parent link="$(arg prefix)front_left_wheel_steer_link"/>-->
<!--      <child link="$(arg prefix)front_left_wheel_traction_link"/>-->
<!--      <origin xyz="0.0 -${wheel_traction_offset_y} -${steer_z+0.0210+suspension_z}"/>-->
<!--  </joint>-->
   
  <link name="$(arg prefix)front_left_wheel_traction_link">
    <visual>
      <origin rpy="0.0 ${PI/2} 0.0" xyz="0.0 ${wheel_width/2} 0.0"/>
      <geometry>
        <mesh filename="package://rbsherpa_hl_description/meshes/wheels/rbsherpa_hl_traction_wheel.dae" />
      </geometry>
<!--      <origin rpy="0.0 ${PI/2} ${PI/2}" xyz="0.0 ${wheel_width/2} 0.0"/>-->
<!--      <geometry>-->
<!--        <cylinder radius="${wheel_radius}" length="${wheel_width}"/>-->
<!--      </geometry>-->
    </visual>
            
    <collision>        
      <origin rpy="0.0 ${PI/2} ${PI/2}" xyz="0.0 ${wheel_width/2} 0.0"/>
      <geometry>
        <cylinder radius="${wheel_radius}" length="${wheel_width}"/>
      </geometry>
    </collision>
    
    <inertial> 
      <origin rpy="0.0 ${PI/2} ${PI/2}" xyz="0.0 ${wheel_width/2} 0.0"/>
	    <mass value="${wheel_mass}" />
	    <cylinder_inertia m="${wheel_mass}" r="${wheel_radius}" h="${wheel_width}"/>
	  </inertial>
  </link>

  <gazebo reference="front_left_wheel_traction_link">
    <material>Gazebo/Grey</material>
    <mu1 value="${mu_1}"/>
  </gazebo>


  <xacro:wheel_steer_transmission prefix="$(arg prefix)front_left_wheel_steer" />
<!--  <xacro:wheel_traction_transmission prefix="$(arg prefix)front_left_wheel_traction" />-->



  <!-- left_front_axle_transmission -->
  <transmission name="$(arg prefix)front_left_wheel_traction_transmission">
    <type>trasnmission_interface/SimpleTransmission</type>
    <joint name="$(arg prefix)front_left_wheel_traction_joint">
      <hardwareInterface>hardware_interface/EffortJointInterface</hardwareInterface>
    </joint>
    <actuator name="$(arg prefix)front_left_wheel_traction_motor">    
      <hardwareInterface>hardware_interface/EffortJointInterface</hardwareInterface>
      <mechanicalReduction>1</mechanicalReduction>
    </actuator>
  </transmission>













<!--  <gazebo reference="left_front_wheel">-->
<!--    <material>Gazebo/Grey</material>-->
<!--			<mu1 value="1.0"/>-->
<!--			<mu2 value="1.0"/>-->
<!--			<kp value="10000000.0" />-->
<!--			<kd value="1.0" />-->
<!--			<fdir1 value="1 0.0 0.0"/>-->
<!--    </gazebo>-->

<!-- Right Steering Wheel -->
  
  <!-- Steering Mechanism -->
 <joint name="$(arg prefix)front_right_wheel_steer_joint" type="revolute">
    <parent link="$(arg prefix)base_link"/>
    <child link="$(arg prefix)front_right_wheel_steer_link"/>
    <origin xyz="${wheel_steer_offset_x} -${wheel_steer_offset_y} ${chassis_field_height+0.010}"/>
    <axis xyz="0 0 1" rpy="0 0 0" />
    <limit effort="30.0" velocity="50.0" lower="${steer_joint_position_limit_lower}" upper="${steer_joint_position_limit_upper}"/>
<!--    <joint_properties damping="${steer_joint_damping}" friction="${steer_joint_friction}"/>-->
  </joint>

<!--  <joint name="$(arg prefix)front_right_wheel_steer_joint" type="fixed">-->
<!--    <parent link="$(arg prefix)base_link"/>-->
<!--    <child link="$(arg prefix)front_right_wheel_steer_link"/>-->
<!--    <origin xyz="${wheel_steer_offset_x} -${wheel_steer_offset_y} ${chassis_field_height+0.010}"/>-->
<!--  </joint>-->
  
  <link name="$(arg prefix)front_right_wheel_steer_link">
    <visual>   
      <origin rpy="0.0 0.0 ${PI}" xyz="0.0 0.0 -${steer_z/2-0.0120}"/>
      <geometry>
        <mesh filename="package://rbsherpa_hl_description/meshes/wheels/rbsherpa_hl_steer_wheel.dae" />
      </geometry>
    </visual>
   
    <inertial> 
      <origin rpy="0.0 0.0 ${PI}" xyz="0.0 0.0 -${steer_z/2}"/>
	    <mass value="0.1" />
	    <!--OLD-->
        <!--<cylinder_inertia m="1.0" r="0.01" h="0.3"/>-->
        <!--NEW-->
        <cylinder_inertia m="0.1" r="0.16" h="0.02"/>
	  </inertial>
  </link>
    <gazebo reference="$(arg prefix)front_right_wheel_steer_link"><material>Gazebo/Grey</material></gazebo>
  

    
   <!-- wheel -->
   
  <joint name="$(arg prefix)front_right_wheel_traction_joint" type="continuous">
      <parent link="$(arg prefix)front_right_wheel_steer_link" />
      <child link="$(arg prefix)front_right_wheel_traction_link"/>
      <origin xyz="0.0 ${wheel_traction_offset_y} -${steer_z+0.0210+suspension_z}"/>
      <axis xyz="0.0 1.0 0.0"/>
  </joint>
   
<!--  <joint name="$(arg prefix)front_right_wheel_traction_joint" type="fixed">-->
<!--      <parent link="$(arg prefix)front_right_wheel_steer_link" />-->
<!--      <child link="$(arg prefix)front_right_wheel_traction_link"/>-->
<!--      <origin xyz="0.0 ${wheel_traction_offset_y} -${steer_z+0.0210+suspension_z}"/>-->
<!--  </joint>-->

  <link name="$(arg prefix)front_right_wheel_traction_link">
    <visual>
      <origin rpy="0.0 ${PI/2} 0.0" xyz="0.0 -${wheel_width/2} 0.0"/>
      <geometry>
        <mesh filename="package://rbsherpa_hl_description/meshes/wheels/rbsherpa_hl_traction_wheel.dae" />
      </geometry>
    </visual>
            
    <collision>        
      <origin rpy="0.0 ${PI/2} ${PI/2}" xyz="0.0 -${wheel_width/2} 0.0"/>
      <geometry>
        <cylinder radius="${wheel_radius}" length="${wheel_width}"/>
      </geometry>
    </collision>
    
    <inertial> 
      <origin rpy="0.0 ${PI/2} ${PI/2}" xyz="0.0 -${wheel_width/2} 0.0"/>
	    <mass value="${wheel_mass}"/>
	    <cylinder_inertia m="${wheel_mass}" r="${wheel_radius}" h="${wheel_width}"/>
	  </inertial>
  </link>

  <xacro:wheel_steer_transmission prefix="$(arg prefix)front_right_wheel_steer" />
  <xacro:wheel_traction_transmission prefix="$(arg prefix)front_right_wheel_traction" />

<!--  <gazebo reference="right_front_wheel">-->
<!--    <material>Gazebo/Grey</material> -->
<!--    <mu1 value="1.0"/>-->
<!--			<mu2 value="1.0"/>-->
<!--			<kp value="10000000.0" />-->
<!--			<kd value="1.0" />-->
<!--			<fdir1 value="1.0 0.0 0.0"/>-->
<!--    </gazebo>   -->
  
<!-- Left rear Wheel -->
  
  <!-- Support-->

  <joint name="$(arg prefix)back_left_wheel_steer_joint" type="revolute">
    <parent link="$(arg prefix)base_link"/>
    <child link="$(arg prefix)back_left_wheel_steer_link"/>
    <origin xyz="-${wheel_steer_offset_x} ${wheel_steer_offset_y} ${chassis_field_height+0.010}"/>
    <axis xyz="0 0 1" rpy="0 0 0" />
    <limit effort="30.0" velocity="50.0" lower="${steer_joint_position_limit_lower}" upper="${steer_joint_position_limit_upper}"/>
<!--    <joint_properties damping="${steer_joint_damping}" friction="${steer_joint_friction}"/>-->
  </joint>

<!--  <joint name="$(arg prefix)back_left_wheel_steer_joint" type="fixed">-->
<!--    <parent link="$(arg prefix)base_link"/>-->
<!--    <child link="$(arg prefix)back_left_wheel_steer_link"/>-->
<!--    <origin xyz="-${wheel_steer_offset_x} ${wheel_steer_offset_y} ${chassis_field_height+0.010}"/>-->
<!--  </joint>-->
  
  <link name="$(arg prefix)back_left_wheel_steer_link">
    <visual>   
      <origin rpy="0.0 0.0 0.0" xyz="0.0 0.0 -${steer_z/2-0.0120}"/>
      <geometry>
        <mesh filename="package://rbsherpa_hl_description/meshes/wheels/rbsherpa_hl_steer_wheel.dae" />
      </geometry>
    </visual>

    <inertial> 
      <origin rpy="0.0 0.0 0.0" xyz="0.0 0.0 -${steer_z/2+0.2}"/>
	    <mass value="0.1" />
	    <!--OLD-->
        <!--<cylinder_inertia m="1.0" r="0.01" h="0.3"/>-->
        <!--NEW-->
        <cylinder_inertia m="0.1" r="0.16" h="0.02"/>

	  </inertial>
  </link>

  <gazebo reference="$(arg prefix)back_left_wheel_steer_link"><material>Gazebo/Grey</material></gazebo>

    
   <!-- wheel -->
   
  <joint name="$(arg prefix)back_left_wheel_traction_joint" type="continuous">
      <parent link="$(arg prefix)back_left_wheel_steer_link" />
      <child link="$(arg prefix)back_left_wheel_traction_link"/>
      <origin xyz="0.0 -${wheel_traction_offset_y} -${steer_z+0.0210+suspension_z}"/>
      <axis xyz="0.0 1.0 0.0"/>
  </joint>

<!--  <joint name="$(arg prefix)back_left_wheel_traction_joint" type="fixed">-->
<!--      <parent link="$(arg prefix)back_left_wheel_steer_link" />-->
<!--      <child link="$(arg prefix)back_left_wheel_traction_link"/>-->
<!--      <origin xyz="0.0 -${wheel_traction_offset_y} -${steer_z+0.0210+suspension_z}"/>-->
<!--  </joint>-->
   
  <link name="$(arg prefix)back_left_wheel_traction_link">
    <visual>
      <origin rpy="0.0 ${PI/2} 0.0" xyz="0.0 ${wheel_width/2} 0.0"/>
      <geometry>
        <mesh filename="package://rbsherpa_hl_description/meshes/wheels/rbsherpa_hl_traction_wheel.dae" />
      </geometry>
    </visual>
            
    <collision>        
      <origin rpy="0.0 ${PI/2} ${PI/2}" xyz="0.0 ${wheel_width/2} 0.0"/>
      <geometry>
        <cylinder radius="${wheel_radius}" length="${wheel_width}"/>
      </geometry>
    </collision>
    
    <inertial> 
      <origin rpy="0.0 ${PI/2} ${PI/2}" xyz="0.0 ${wheel_width/2} 0.0"/>
	    <mass value="${wheel_mass}" />
	    <cylinder_inertia m="${wheel_mass}" r="${wheel_radius}" h="${wheel_width}"/>
	  </inertial>
  </link>

  <xacro:wheel_steer_transmission prefix="$(arg prefix)back_left_wheel_steer" />
  <xacro:wheel_traction_transmission prefix="$(arg prefix)back_left_wheel_traction" />

<!--  <gazebo reference="left_rear_wheel">-->
<!--    <material>Gazebo/Grey</material> -->
<!--    <mu1 value="1.0"/>-->
<!--			<mu2 value="1.0"/>-->
<!--			<kp value="10000000.0" />-->
<!--			<kd value="1.0" />-->
<!--			<fdir1 value="1.0 0.0 0.0"/>-->
<!--    </gazebo>   -->
   
    

<!-- Right Rear Wheel -->
  
  <!-- Support -->
 
 <joint name="$(arg prefix)back_right_wheel_steer_joint" type="revolute">
    <parent link="$(arg prefix)base_link"/>
    <child link="$(arg prefix)back_right_wheel_steer_link"/>
    <origin xyz="-${wheel_steer_offset_x} -${wheel_steer_offset_y} ${chassis_field_height+0.010}"/>
    <axis xyz="0 0 1" rpy="0 0 0" />
    <limit effort="30.0" velocity="50.0" lower="${steer_joint_position_limit_lower}" upper="${steer_joint_position_limit_upper}"/>
<!--    <joint_properties damping="${steer_joint_damping}" friction="${steer_joint_friction}"/>-->
  </joint>

<!-- <joint name="$(arg prefix)back_right_wheel_steer_joint" type="fixed">-->
<!--    <parent link="$(arg prefix)base_link"/>-->
<!--    <child link="$(arg prefix)back_right_wheel_steer_link"/>-->
<!--    <origin xyz="-${wheel_steer_offset_x} -${wheel_steer_offset_y} ${chassis_field_height+0.010}"/>-->
<!--  </joint>-->
  
  <link name="$(arg prefix)back_right_wheel_steer_link">
    <visual>   

      <origin rpy="0.0 0.0 ${PI}" xyz="0.0 0.0 -${steer_z/2-0.0120}"/>
      <geometry>
        <mesh filename="package://rbsherpa_hl_description/meshes/wheels/rbsherpa_hl_steer_wheel.dae" />
      </geometry>
    </visual>
   
    <inertial> 
      <origin rpy="0.0 0.0 ${PI}" xyz="0.0 0.0 -${steer_z/2+0.2}"/>
	    <mass value="0.1" />
	    <!--OLD-->
        <!--<cylinder_inertia m="1.0" r="0.01" h="0.3"/>-->
        <!--NEW-->
        <cylinder_inertia m="0.1" r="0.16" h="0.02"/>
	  </inertial>
  </link>
  
    <gazebo reference="$(arg prefix)back_right_wheel_steer_link"><material>Gazebo/Grey</material></gazebo>

    
   <!-- wheel -->
   
  <joint name="$(arg prefix)back_right_wheel_traction_joint" type="continuous">
      <parent link="$(arg prefix)back_right_wheel_steer_link" />
      <child link="$(arg prefix)back_right_wheel_traction_link"/>
      <origin xyz="0.0 ${wheel_traction_offset_y} -${steer_z+0.0210+suspension_z}"/>
      <axis xyz="0.0 1 0.0"/>
  </joint>

<!--  <joint name="$(arg prefix)back_right_wheel_traction_joint" type="fixed">-->
<!--      <parent link="$(arg prefix)back_right_wheel_steer_link" />-->
<!--      <child link="$(arg prefix)back_right_wheel_traction_link"/>-->
<!--      <origin xyz="0.0 ${wheel_traction_offset_y} -${steer_z+0.0210+suspension_z}"/>-->
<!--  </joint>-->
   
  <link name="$(arg prefix)back_right_wheel_traction_link">
    <visual>
      <origin rpy="0.0 ${PI/2} 0.0" xyz="0.0 -${wheel_width/2} 0.0"/>
      <geometry>
        <mesh filename="package://rbsherpa_hl_description/meshes/wheels/rbsherpa_hl_traction_wheel.dae" />
      </geometry>
    </visual>
            
    <collision>        
      <origin rpy="0.0 ${PI/2} ${PI/2}" xyz="0.0 -${wheel_width/2} 0"/>
      <geometry>
        <cylinder radius="${wheel_radius}" length="${wheel_width}"/>
      </geometry>
    </collision>
    
    <inertial> 
      <origin rpy="0.0 ${PI/2} ${PI/2}" xyz="0.0 -${wheel_width/2} 0.0"/>
	    <mass value="${wheel_mass}" />
	    <cylinder_inertia m="${wheel_mass}" r="${wheel_radius}" h="${wheel_width}"/>
	  </inertial>
  </link>

  <xacro:wheel_steer_transmission prefix="$(arg prefix)back_right_wheel_steer" />
  <xacro:wheel_traction_transmission prefix="$(arg prefix)back_right_wheel_traction" />


<!--  <gazebo reference="right_rear_wheel">-->
<!--    <material>Gazebo/Grey</material> -->
<!--    <mu1 value="1.0"/>-->
<!--			<mu2 value="1.0"/>-->
<!--			<kp value="10000000.0" />-->
<!--			<kd value="1.0" />-->
<!--			<fdir1 value="1.0 0.0 0.0"/>-->
<!--    </gazebo>  -->

















  
</robot>
