<?xml version="1.0"?>

<robot name ="arm" xmlns:xacro="http://www.ros.org/wiki/xacro">

    <xacro:property name="PI" value="3.1415926535897931"/>

    <!-- Box Inertia -->
    <xacro:macro name="box_inertia" params="m h w d">
        <inertia 	ixx="${m*(w*w+d*d)/12}" ixy = "0" ixz = "0"
			        iyy="${m*(d*d+h*h)/12}" iyz = "0"
			        izz="${m*(w*w+h*h)/12}" />
    </xacro:macro>



    <!-- Gimball -->

    <link name="box_link">
        <visual>
            <origin rpy="0 0 0" xyz="0 0 0"/>
            <geometry>
                <box size="1 1 1"/>
            </geometry>
            <material name="red"/>
        </visual>

        <collision>
            <origin rpy="0 0 0" xyz="0 0 0.5"/>
            <geometry>
                <box size="1 1 1"/>
            </geometry>
        </collision>
    </link>
 

	<joint name="box_link_to_support_yaw_joint" type="fixed">
		<parent link="box_link"/>
		<child link="support_yaw"/>
        <origin xyz="1.0 0 1.0 " rpy="0 0 0"/>
		<!-- <origin xyz="-0.45470 0 -${0.15180/2} " rpy="0 0 0"/> -->
	</joint>
	

	<link name="support_yaw">
		
		<visual>
			<origin xyz="+0.4547 0 0" rpy="0 0 0"/>
			<geometry>
				<mesh filename="package://sherpa_ros/description/meshes/gimbal_support_yaw.dae" />
			</geometry>
		</visual>
		
		<inertial>
			<mass value="1.0" />
			<origin xyz="0 0 0" rpy="0 0 0"/>
			<box_inertia  m="1.0" h="0.040" w ="0.040" d="0.15180"/>
		</inertial>	
	</link>
	<gazebo reference="support_yaw"><material>Gazebo/Grey</material></gazebo>	
	
	<joint name="gimbal_yaw_joint" type="revolute">
		<parent link="torso_pantilt_pan_link"/>
		<child link="gimbal_yaw_link"/>
		<origin xyz="-0.45580 0.01290 -0.14820" rpy="0 0 0"/>
		<axis xyz="0 0 -1"/>
		<limit effort="30.0" velocity="50.0" lower="-${3.14}" upper="${3.14}"/>
	</joint>
	
	<link name="gimbal_yaw_link">
		
		<visual>
			<origin xyz="0.45470 0 0.08180" rpy="0 0 0"/>
			<geometry>
				<mesh filename="package://sherpa_ros/description/meshes/gimbal_yaw.dae" />
			</geometry>
		</visual>
		
		<inertial>
			<mass value="1.0" />
			<origin xyz="0 0 0" rpy="0 0 0"/>
			<box_inertia  m="1.0" h="0.340" w ="0.050" d="0.020"/>
		</inertial>	
	</link>
	
	<gazebo reference="gimbal_yaw_link"><material>Gazebo/Grey</material></gazebo>

	<joint name="gimbal_roll_joint" type="revolute">
		<parent link="gimbal_yaw_link"/>
		<child link="gimbal_roll_link"/>
		<origin xyz="0.14220 -0.00680 -0.14330" rpy="0.0 0.0 0.0"/>
		<axis xyz="1.0 0.0 0.0"/>
		<limit effort="30.0" velocity="50.0" lower="-${PI/2}" upper="${PI/2}"/>
	</joint>
	
	<link name="gimbal_roll_link">
		
		<visual>
			<origin xyz="0.310 0.0050 0.220" rpy="0.0 0.0 0.0"/>
			<geometry>
				<mesh filename="package://sherpa_ros/description/meshes/gimbal_roll.dae" />
			</geometry>
		</visual>
		
		<inertial>
			<mass value="2.0" />
			<origin xyz="0.0 0.0 0.0" rpy="0.0 0.0 0.0"/>
			<box_inertia  m="1.0" h="0.20" w ="0.340" d="0.050"/>
		</inertial>
			
	</link>
	
	<gazebo reference="gimbal_roll_link"><material>Gazebo/Grey</material></gazebo>	
	
	<joint name="gimbal_pitch_joint" type="revolute">
		<parent link="gimbal_roll_link"/>
		<child link="gimbal_pitch_link"/>
		<origin xyz="-0.18120 -0.13220 -0.00340" rpy="0.0 0.0 0.0"/>
		<axis xyz="0.0 -1 0.0"/>
		<limit effort="30.0" velocity="50.0" lower="-${PI/2}" upper="${PI/2}"/>
	</joint>
	
	
	<link name="gimbal_pitch_link">
		
		<visual>
			<origin xyz="-0.480 0.13780 0.21850" rpy="0.0 0.0 ${PI}"/>
			<geometry>
				<mesh filename="package://sherpa_ros/description/meshes/gimbal_pitch.dae" />
			</geometry>
		</visual>
		
		<inertial>
			<mass value="1.0"/>
			<origin xyz="0.0 0.140 0.0" rpy="0.0 0.0 0.0"/>
			<box_inertia  m="1.0" h="0.0050" w ="0.20" d="0.190"/>
		</inertial>	
	</link>
	<gazebo reference="gimbal_pitch_link"><material>Gazebo/Grey</material></gazebo>	
	
	
	<joint name="camera_joint" type="fixed">
		<parent link="gimbal_pitch_link"/>
		<child link="camera"/>
		<origin xyz="0.02040 0.14450 -0.00710" rpy="0.0 0.0 0.0"/>
	</joint>

</robot>
